Workbook

Sheet DASHBOARD
A1: CONTAINER TERMINAL DASHBOARD
A2: Vessel calls and volume summary · 2024 – 2026
A4: KEY PERFORMANCE INDICATORS
A5: METRIC | B5: 2024 | C5: 2025 | D5: 2026 (YTD) | E5: Δ 25 / 24
A6: Vessel calls (voyages) | B6: =COUNT('2024'!$E$3:$E$500) -> 103 | C6: =COUNT('2025'!$E$3:$E$500) -> 101 | D6: =COUNT('2026'!$E$3:$E$500) -> 74 | E6: =IFERROR(C6/B6-1,"") -> -0.019417476
A7: Total TEU | B7: =SUM(B42:B47) -> 108070 | C7: =SUM(C42:C47) -> 113600 | D7: =SUM(D42:D47) -> 85478 | E7: =IFERROR(C7/B7-1,"") -> 0.051170538
A8: Total containers | B8: =B42+B43/2+B44+B45/2+B46+B47/2 -> 72060 | C8: =C42+C43/2+C44+C45/2+C46+C47/2 -> 73243 | D8: =D42+D43/2+D44+D45/2+D46+D47/2 -> 54776 | E8: =IFERROR(C8/B8-1,"") -> 0.016416875
A9: Avg. TEU per call | B9: =IFERROR(B7/B6,0) -> 1049.2233 | C9: =IFERROR(C7/C6,0) -> 1124.7525 | D9: =IFERROR(D7/D6,0) -> 1155.1081 | E9: =IFERROR(C9/B9-1,"") -> 0.071985796
A10: Containers discharged | B10: =B42+B43/2 -> 35969 | C10: =C42+C43/2 -> 36728 | D10: =D42+D43/2 -> 27719 | E10: =IFERROR(C10/B10-1,"") -> 0.021101504
A11: Containers loaded (FCL + empty) | B11: =B8-B10 -> 36091 | C11: =C8-C10 -> 36515 | D11: =D8-D10 -> 27057 | E11: =IFERROR(C11/B11-1,"") -> 0.011748081
A12: Share of 40' containers | B12: =IFERROR((B43+B45+B47)/2/B8,0) -> 0.49972245 | C12: =IFERROR((C43+C45+C47)/2/C8,0) -> 0.55100146 | D12: =IFERROR((D43+D45+D47)/2/D8,0) -> 0.56050095 | E12: =IFERROR(C12/B12-1,"") -> 0.10261498
A15: MONTHLY TEU
A16: MONTH | B16: 2024 | C16: 2025 | D16: 2026 | E16: Δ 25 / 24 | F16: Δ 26 / 25
A17: January | B17: =SUMIF('2024'!$A$3:$A$500,$A17,'2024'!$O$3:$O$500) -> 8288 | C17: =SUMIF('2025'!$A$3:$A$500,$A17,'2025'!$O$3:$O$500) -> 11995 | D17: =IF(SUMIF('2026'!$Q$3:$Q$500,$A17,'2026'!$R$3:$R$500)=0,"",SUMIF('2026'!$Q$3:$Q$500,$A17,'2026'!$R$3:$R$500)) -> 14666 | E17: =IFERROR(C17/B17-1,"") -> 0.44727317 | F17: =IF(D17=0,"",IFERROR(D17/C17-1,"")) -> 0.22267612
A18: February | B18: =SUMIF('2024'!$A$3:$A$500,$A18,'2024'!$O$3:$O$500) -> 8833 | C18: =SUMIF('2025'!$A$3:$A$500,$A18,'2025'!$O$3:$O$500) -> 6492 | D18: =IF(SUMIF('2026'!$Q$3:$Q$500,$A18,'2026'!$R$3:$R$500)=0,"",SUMIF('2026'!$Q$3:$Q$500,$A18,'2026'!$R$3:$R$500)) -> 5123 | E18: =IFERROR(C18/B18-1,"") -> -0.26502887 | F18: =IF(D18=0,"",IFERROR(D18/C18-1,"")) -> -0.21087492
A19: March | B19: =SUMIF('2024'!$A$3:$A$500,$A19,'2024'!$O$3:$O$500) -> 11055 | C19: =SUMIF('2025'!$A$3:$A$500,$A19,'2025'!$O$3:$O$500) -> 9243 | D19: =IF(SUMIF('2026'!$Q$3:$Q$500,$A19,'2026'!$R$3:$R$500)=0,"",SUMIF('2026'!$Q$3:$Q$500,$A19,'2026'!$R$3:$R$500)) -> 12744 | E19: =IFERROR(C19/B19-1,"") -> -0.16390773 | F19: =IF(D19=0,"",IFERROR(D19/C19-1,"")) -> 0.37877313
A20: April | B20: =SUMIF('2024'!$A$3:$A$500,$A20,'2024'!$O$3:$O$500) -> 11436 | C20: =SUMIF('2025'!$A$3:$A$500,$A20,'2025'!$O$3:$O$500) -> 11218 | D20: =IF(SUMIF('2026'!$Q$3:$Q$500,$A20,'2026'!$R$3:$R$500)=0,"",SUMIF('2026'!$Q$3:$Q$500,$A20,'2026'!$R$3:$R$500)) -> 12671 | E20: =IFERROR(C20/B20-1,"") -> -0.019062609 | F20: =IF(D20=0,"",IFERROR(D20/C20-1,"")) -> 0.12952398
A21: May | B21: =SUMIF('2024'!$A$3:$A$500,$A21,'2024'!$O$3:$O$500) -> 9569 | C21: =SUMIF('2025'!$A$3:$A$500,$A21,'2025'!$O$3:$O$500) -> 10414 | D21: =IF(SUMIF('2026'!$Q$3:$Q$500,$A21,'2026'!$R$3:$R$500)=0,"",SUMIF('2026'!$Q$3:$Q$500,$A21,'2026'!$R$3:$R$500)) -> 10628 | E21: =IFERROR(C21/B21-1,"") -> 0.088305988 | F21: =IF(D21=0,"",IFERROR(D21/C21-1,"")) -> 0.020549261
A22: June | B22: =SUMIF('2024'!$A$3:$A$500,$A22,'2024'!$O$3:$O$500) -> 8583 | C22: =SUMIF('2025'!$A$3:$A$500,$A22,'2025'!$O$3:$O$500) -> 11653 | D22: =IF(SUMIF('2026'!$Q$3:$Q$500,$A22,'2026'!$R$3:$R$500)=0,"",SUMIF('2026'!$Q$3:$Q$500,$A22,'2026'!$R$3:$R$500)) -> 15639 | E22: =IFERROR(C22/B22-1,"") -> 0.35768379 | F22: =IF(D22=0,"",IFERROR(D22/C22-1,"")) -> 0.34205784
A23: July | B23: =SUMIF('2024'!$A$3:$A$500,$A23,'2024'!$O$3:$O$500) -> 9802 | C23: =SUMIF('2025'!$A$3:$A$500,$A23,'2025'!$O$3:$O$500) -> 8887 | D23: =IF(SUMIF('2026'!$Q$3:$Q$500,$A23,'2026'!$R$3:$R$500)=0,"",SUMIF('2026'!$Q$3:$Q$500,$A23,'2026'!$R$3:$R$500)) -> 8283 | E23: =IFERROR(C23/B23-1,"") -> -0.093348296 | F23: =IF(D23=0,"",IFERROR(D23/C23-1,"")) -> -0.067964442
A24: August | B24: =SUMIF('2024'!$A$3:$A$500,$A24,'2024'!$O$3:$O$500) -> 6891 | C24: =SUMIF('2025'!$A$3:$A$500,$A24,'2025'!$O$3:$O$500) -> 8585 | D24: =IF(SUMIF('2026'!$Q$3:$Q$500,$A24,'2026'!$R$3:$R$500)=0,"",SUMIF('2026'!$Q$3:$Q$500,$A24,'2026'!$R$3:$R$500)) -> 5724 | E24: =IFERROR(C24/B24-1,"") -> 0.24582789 | F24: =IF(D24=0,"",IFERROR(D24/C24-1,"")) -> -0.33325568
A25: September | B25: =SUMIF('2024'!$A$3:$A$500,$A25,'2024'!$O$3:$O$500) -> 7760 | C25: =SUMIF('2025'!$A$3:$A$500,$A25,'2025'!$O$3:$O$500) -> 8101 | D25: =IF(SUMIF('2026'!$Q$3:$Q$500,$A25,'2026'!$R$3:$R$500)=0,"",SUMIF('2026'!$Q$3:$Q$500,$A25,'2026'!$R$3:$R$500)) | E25: =IFERROR(C25/B25-1,"") -> 0.043943299 | F25: =IF(D25=0,"",IFERROR(D25/C25-1,""))
A26: October | B26: =SUMIF('2024'!$A$3:$A$500,$A26,'2024'!$O$3:$O$500) -> 9141 | C26: =SUMIF('2025'!$A$3:$A$500,$A26,'2025'!$O$3:$O$500) -> 9140 | D26: =IF(SUMIF('2026'!$Q$3:$Q$500,$A26,'2026'!$R$3:$R$500)=0,"",SUMIF('2026'!$Q$3:$Q$500,$A26,'2026'!$R$3:$R$500)) | E26: =IFERROR(C26/B26-1,"") -> -0.00010939722 | F26: =IF(D26=0,"",IFERROR(D26/C26-1,""))
A27: November | B27: =SUMIF('2024'!$A$3:$A$500,$A27,'2024'!$O$3:$O$500) -> 7079 | C27: =SUMIF('2025'!$A$3:$A$500,$A27,'2025'!$O$3:$O$500) -> 10012 | D27: =IF(SUMIF('2026'!$Q$3:$Q$500,$A27,'2026'!$R$3:$R$500)=0,"",SUMIF('2026'!$Q$3:$Q$500,$A27,'2026'!$R$3:$R$500)) | E27: =IFERROR(C27/B27-1,"") -> 0.41432406 | F27: =IF(D27=0,"",IFERROR(D27/C27-1,""))
A28: December | B28: =SUMIF('2024'!$A$3:$A$500,$A28,'2024'!$O$3:$O$500) -> 9633 | C28: =SUMIF('2025'!$A$3:$A$500,$A28,'2025'!$O$3:$O$500) -> 7860 | D28: =IF(SUMIF('2026'!$Q$3:$Q$500,$A28,'2026'!$R$3:$R$500)=0,"",SUMIF('2026'!$Q$3:$Q$500,$A28,'2026'!$R$3:$R$500)) | E28: =IFERROR(C28/B28-1,"") -> -0.18405481 | F28: =IF(D28=0,"",IFERROR(D28/C28-1,""))
A29: TOTAL | B29: =SUM(B17:B28) -> 108070 | C29: =SUM(C17:C28) -> 113600 | D29: =SUM(D17:D28) -> 85478 | E29: =IFERROR(C29/B29-1,"") -> 0.051170538
A31: AGENT PERFORMANCE
A32: AGENT | B32: Calls 2024 | C32: Calls 2025 | D32: Calls 2026 | E32: TEU 2026 | F32: Share 2026
A33: CMA | B33: =COUNTIF('2024'!$D$3:$D$500,$A33) -> 23 | C33: =COUNTIF('2025'!$D$3:$D$500,$A33) -> 17 | D33: =COUNTIF('2026'!$D$3:$D$500,$A33) -> 15 | E33: =SUMIF('2026'!$D$3:$D$500,$A33,'2026'!$R$3:$R$500) -> 14758 | F33: =IFERROR(E33/$E$37,"") -> 0.17265261
A34: MAE | B34: =COUNTIF('2024'!$D$3:$D$500,$A34) -> 42 | C34: =COUNTIF('2025'!$D$3:$D$500,$A34) -> 43 | D34: =COUNTIF('2026'!$D$3:$D$500,$A34) -> 31 | E34: =SUMIF('2026'!$D$3:$D$500,$A34,'2026'!$R$3:$R$500) -> 43512 | F34: =IFERROR(E34/$E$37,"") -> 0.50904326
A35: MSC | B35: =COUNTIF('2024'!$D$3:$D$500,$A35) -> 21 | C35: =COUNTIF('2025'!$D$3:$D$500,$A35) -> 27 | D35: =COUNTIF('2026'!$D$3:$D$500,$A35) -> 20 | E35: =SUMIF('2026'!$D$3:$D$500,$A35,'2026'!$R$3:$R$500) -> 18781 | F35: =IFERROR(E35/$E$37,"") -> 0.21971735
A36: OBT | B36: =COUNTIF('2024'!$D$3:$D$500,$A36) -> 16 | C36: =COUNTIF('2025'!$D$3:$D$500,$A36) -> 14 | D36: =COUNTIF('2026'!$D$3:$D$500,$A36) -> 8 | E36: =SUMIF('2026'!$D$3:$D$500,$A36,'2026'!$R$3:$R$500) -> 8427 | F36: =IFERROR(E36/$E$37,"") -> 0.098586771
A37: TOTAL | B37: =SUM(B33:B36) -> 102 | C37: =SUM(C33:C36) -> 101 | D37: =SUM(D33:D36) -> 74 | E37: =SUM(E33:E36) -> 85478 | F37: =IFERROR(E37/$E$37,"") -> 1
A40: CONTAINER BREAKDOWN (TEU)
A41: CATEGORY | B41: 2024 | C41: 2025 | D41: 2026
A42: Discharge 20' | B42: =SUMIF('2024'!$E$3:$E$500,">0",'2024'!G$3:G$500) -> 18100 | C42: =SUMIF('2025'!$E$3:$E$500,">0",'2025'!G$3:G$500) -> 16405 | D42: =SUMIF('2026'!$E$3:$E$500,">0",'2026'!G$3:G$500) -> 12186
A43: Discharge 40' | B43: =2*SUMIF('2024'!$E$3:$E$500,">0",'2024'!H$3:H$500) -> 35738 | C43: =2*SUMIF('2025'!$E$3:$E$500,">0",'2025'!H$3:H$500) -> 40646 | D43: =2*SUMIF('2026'!$E$3:$E$500,">0",'2026'!H$3:H$500) -> 31066
A44: FCL loading 20' | B44: =SUMIF('2024'!$E$3:$E$500,">0",'2024'!I$3:I$500) -> 3406 | C44: =SUMIF('2025'!$E$3:$E$500,">0",'2025'!I$3:I$500) -> 3250 | D44: =SUMIF('2026'!$E$3:$E$500,">0",'2026'!I$3:I$500) -> 2668
A45: FCL loading 40' | B45: =2*SUMIF('2024'!$E$3:$E$500,">0",'2024'!J$3:J$500) -> 6266 | C45: =2*SUMIF('2025'!$E$3:$E$500,">0",'2025'!J$3:J$500) -> 8306 | D45: =2*SUMIF('2026'!$E$3:$E$500,">0",'2026'!J$3:J$500) -> 8748
A46: Empty loading 20' | B46: =SUMIF('2024'!$E$3:$E$500,">0",'2024'!K$3:K$500) -> 14544 | C46: =SUMIF('2025'!$E$3:$E$500,">0",'2025'!K$3:K$500) -> 13231 | D46: =SUMIF('2026'!$E$3:$E$500,">0",'2026'!K$3:K$500) -> 9220
...

Sheet 2026
A1: MONTH | B1: NO | C1: VESSEL NAME | D1: AGENT | E1: BERTHING | F1: DEPARTURE | G1: DISCHARGE | I1: FCL LOADING | K1: EMPTY LOADING | M1: HATCH COVER | N1: TOTAL TEU | O1: TOTAL CONTAINERS | P1: MONTHLY TEU | Q1: MONTH (auto) | R1: TEU (auto) | S1: CONTAINER (auto)
G2: 20 | H2: 40 | I2: 20 | J2: 40 | K2: 20 | L2: 40
A3: January | B3: =COUNTA(C3:C15) -> 13 | C3: BF ESPERANZA | D3: MAE | E3: 46022.956 | F3: 46027.493 | G3: 197 | H3: 125 | I3: 42 | J3: 77 | K3: 32 | L3: 156 | M3: 8 | N3: =G3+H3*2+I3+J3*2+K3+L3*2 -> 987 | O3: =SUM(G3:L3) -> 629 | P3: =SUM(N3:N15) -> 14666 | Q3: =IF($A3<>"",$A3,Q2) -> January | R3: =IF($E3>0,$G3+2*$H3+$I3+2*$J3+$K3+2*$L3,0) -> 987 | S3: =IF($E3>0,SUM($G3:$L3),0) -> 629
C4: MAERSK DURBAN | D4: MAE | E4: 46021.983 | F4: 46023.758 | G4: 122 | H4: 492 | I4: 0 | J4: 0 | K4: 0 | L4: 1 | M4: 35 | N4: =G4+H4*2+I4+J4*2+K4+L4*2 -> 1108 | O4: =SUM(G4:L4) -> 615 | Q4: =IF($A4<>"",$A4,Q3) -> January | R4: =IF($E4>0,$G4+2*$H4+$I4+2*$J4+$K4+2*$L4,0) -> 1108 | S4: =IF($E4>0,SUM($G4:$L4),0) -> 615
C5: JONATHAN P | D5: CMA | E5: 46027.575 | F5: 46030.613 | G5: 109 | H5: 148 | I5: 31 | J5: 53 | K5: 106 | L5: 89 | M5: 14 | N5: =G5+H5*2+I5+J5*2+K5+L5*2 -> 826 | O5: =SUM(G5:L5) -> 536 | Q5: =IF($A5<>"",$A5,Q4) -> January | R5: =IF($E5>0,$G5+2*$H5+$I5+2*$J5+$K5+2*$L5,0) -> 826 | S5: =IF($E5>0,SUM($G5:$L5),0) -> 536
C6: MSC WAVE F | D6: MSC | E6: 46027.99 | F6: 46031.039 | G6: 205 | H6: 154 | I6: 9 | J6: 8 | K6: 280 | L6: 174 | M6: 0 | N6: =G6+H6*2+I6+J6*2+K6+L6*2 -> 1166 | O6: =SUM(G6:L6) -> 830 | Q6: =IF($A6<>"",$A6,Q5) -> January | R6: =IF($E6>0,$G6+2*$H6+$I6+2*$J6+$K6+2*$L6,0) -> 1166 | S6: =IF($E6>0,SUM($G6:$L6),0) -> 830
C7: EF ELDRA | D7: MAE | E7: 46031.133 | F7: 46035.621 | G7: 84 | H7: 408 | I7: 119 | J7: 196 | K7: 109 | L7: 164 | M7: 28 | N7: =G7+H7*2+I7+J7*2+K7+L7*2 -> 1848 | O7: =SUM(G7:L7) -> 1080 | Q7: =IF($A7<>"",$A7,Q6) -> January | R7: =IF($E7>0,$G7+2*$H7+$I7+2*$J7+$K7+2*$L7,0) -> 1848 | S7: =IF($E7>0,SUM($G7:$L7),0) -> 1080
C8: AURETTE A | D8: CMA | E8: 46035.622 | F8: 46038.094 | G8: 208 | H8: 228 | I8: 2 | J8: 38 | K8: 158 | L8: 189 | M8: 22 | N8: =G8+H8*2+I8+J8*2+K8+L8*2 -> 1278 | O8: =SUM(G8:L8) -> 823 | Q8: =IF($A8<>"",$A8,Q7) -> January | R8: =IF($E8>0,$G8+2*$H8+$I8+2*$J8+$K8+2*$L8,0) -> 1278 | S8: =IF($E8>0,SUM($G8:$L8),0) -> 823
C9: MATILDE A | D9: OBT | E9: 46038.156 | F9: 46040.117 | G9: 72 | H9: 168 | I9: 1 | J9: 7 | K9: 74 | L9: 187 | M9: 14 | N9: =G9+H9*2+I9+J9*2+K9+L9*2 -> 871 | O9: =SUM(G9:L9) -> 509 | Q9: =IF($A9<>"",$A9,Q8) -> January | R9: =IF($E9>0,$G9+2*$H9+$I9+2*$J9+$K9+2*$L9,0) -> 871 | S9: =IF($E9>0,SUM($G9:$L9),0) -> 509
C10: MSC WAVE F | D10: MSC | E10: 46040.372 | F10: 46043.485 | G10: 237 | H10: 155 | I10: 4 | J10: 10 | K10: 155 | L10: 120 | M10: 0 | N10: =G10+H10*2+I10+J10*2+K10+L10*2 -> 966 | O10: =SUM(G10:L10) -> 681 | Q10: =IF($A10<>"",$A10,Q9) -> January | R10: =IF($E10>0,$G10+2*$H10+$I10+2*$J10+$K10+2*$L10,0) -> 966 | S10: =IF($E10>0,SUM($G10:$L10),0) -> 681
C11: SALGUEIRO | D11: MAE | E11: 46039.569 | F11: 46043.314 | G11: 212 | H11: 198 | I11: 32 | J11: 103 | K11: 258 | L11: 178 | M11: 26 | N11: =G11+H11*2+I11+J11*2+K11+L11*2 -> 1460 | O11: =SUM(G11:L11) -> 981 | Q11: =IF($A11<>"",$A11,Q10) -> January | R11: =IF($E11>0,$G11+2*$H11+$I11+2*$J11+$K11+2*$L11,0) -> 1460 | S11: =IF($E11>0,SUM($G11:$L11),0) -> 981
C12: LION | D12: CMA | E12: 46043.451 | F12: 46045.858 | G12: 137 | H12: 150 | I12: 0 | J12: 90 | K12: 42 | L12: 21 | M12: 24 | N12: =G12+H12*2+I12+J12*2+K12+L12*2 -> 701 | O12: =SUM(G12:L12) -> 440 | Q12: =IF($A12<>"",$A12,Q11) -> January | R12: =IF($E12>0,$G12+2*$H12+$I12+2*$J12+$K12+2*$L12,0) -> 701 | S12: =IF($E12>0,SUM($G12:$L12),0) -> 440
C13: BF ESPERANZA | D13: MAE | E13: 46043.576 | F13: 46047.506 | G13: 62 | H13: 218 | I13: 36 | J13: 96 | K13: 89 | L13: 199 | M13: 8 | N13: =G13+H13*2+I13+J13*2+K13+L13*2 -> 1213 | O13: =SUM(G13:L13) -> 700 | Q13: =IF($A13<>"",$A13,Q12) -> January | R13: =IF($E13>0,$G13+2*$H13+$I13+2*$J13+$K13+2*$L13,0) -> 1213 | S13: =IF($E13>0,SUM($G13:$L13),0) -> 700
C14: MAERSK REGENSBURG | D14: MAE | E14: 46046.664 | F14: 46050.354 | G14: 133 | H14: 266 | I14: 58 | J14: 38 | K14: 101 | L14: 292 | M14: 26 | N14: =G14+H14*2+I14+J14*2+K14+L14*2 -> 1484 | O14: =SUM(G14:L14) -> 888 | Q14: =IF($A14<>"",$A14,Q13) -> January | R14: =IF($E14>0,$G14+2*$H14+$I14+2*$J14+$K14+2*$L14,0) -> 1484 | S14: =IF($E14>0,SUM($G14:$L14),0) -> 888
C15: MSC TIANA F | D15: MSC | E15: 46048.65 | F15: 46050.946 | G15: 333 | H15: 32 | I15: 1 | J15: 0 | K15: 120 | L15: 120 | M15: 28 | N15: =G15+H15*2+I15+J15*2+K15+L15*2 -> 758 | O15: =SUM(G15:L15) -> 606 | Q15: =IF($A15<>"",$A15,Q14) -> January | R15: =IF($E15>0,$G15+2*$H15+$I15+2*$J15+$K15+2*$L15,0) -> 758 | S15: =IF($E15>0,SUM($G15:$L15),0) -> 606
A16: February | B16: =COUNTA(C16:C20) -> 5 | C16: HORIZON | D16: MAE | E16: 46053.429 | F16: 46058.033 | G16: 102 | H16: 348 | I16: 91 | J16: 200 | K16: 58 | L16: 196 | M16: 26 | N16: =G16+H16*2+I16+J16*2+K16+L16*2 -> 1739 | O16: =SUM(G16:L16) -> 995 | P16: =SUM(N16:N20) -> 5123 | Q16: =IF($A16<>"",$A16,Q15) -> February | R16: =IF($E16>0,$G16+2*$H16+$I16+2*$J16+$K16+2*$L16,0) -> 1739 | S16: =IF($E16>0,SUM($G16:$L16),0) -> 995
C17: CONTSHIP NEW | D17: MSC | E17: 46054.733 | F17: 46056.773 | G17: 207 | H17: 94 | I17: 0 | J17: 0 | K17: 195 | L17: 41 | M17: 16 | N17: =G17+H17*2+I17+J17*2+K17+L17*2 -> 672 | O17: =SUM(G17:L17) -> 537 | Q17: =IF($A17<>"",$A17,Q16) -> February | R17: =IF($E17>0,$G17+2*$H17+$I17+2*$J17+$K17+2*$L17,0) -> 672 | S17: =IF($E17>0,SUM($G17:$L17),0) -> 537
C18: MSC TIANA F | D18: MSC | E18: 46069.054 | F18: 46071.792 | G18: 330 | H18: 32 | I18: 7 | J18: 4 | K18: 396 | L18: 111 | M18: 28 | N18: =G18+H18*2+I18+J18*2+K18+L18*2 -> 1027 | O18: =SUM(G18:L18) -> 880 | Q18: =IF($A18<>"",$A18,Q17) -> February | R18: =IF($E18>0,$G18+2*$H18+$I18+2*$J18+$K18+2*$L18,0) -> 1027 | S18: =IF($E18>0,SUM($G18:$L18),0) -> 880
C19: MATILDE A | D19: OBT | E19: 46070.979 | F19: 46074.363 | G19: 86 | H19: 195 | I19: 1 | J19: 64 | K19: 80 | L19: 147 | M19: 14 | N19: =G19+H19*2+I19+J19*2+K19+L19*2 -> 979 | O19: =SUM(G19:L19) -> 573 | Q19: =IF($A19<>"",$A19,Q18) -> February | R19: =IF($E19>0,$G19+2*$H19+$I19+2*$J19+$K19+2*$L19,0) -> 979 | S19: =IF($E19>0,SUM($G19:$L19),0) -> 573
C20: MSC AMANDA F | D20: MSC | E20: 46074.451 | F20: 46076.74 | G20: 260 | H20: 96 | I20: 0 | J20: 11 | K20: 214 | L20: 9 | M20: 26 | N20: =G20+H20*2+I20+J20*2+K20+L20*2 -> 706 | O20: =SUM(G20:L20) -> 590 | Q20: =IF($A20<>"",$A20,Q19) -> February | R20: =IF($E20>0,$G20+2*$H20+$I20+2*$J20+$K20+2*$L20,0) -> 706 | S20: =IF($E20>0,SUM($G20:$L20),0) -> 590
A21: March | B21: =COUNTA(C21:C31) -> 11 | C21: MAERSK REGENSBURG | D21: MAE | E21: 46087.63 | F21: 46091.367 | G21: 71 | H21: 296 | I21: 98 | J21: 210 | K21: 16 | L21: 108 | M21: 26 | N21: =G21+H21*2+I21+J21*2+K21+L21*2 -> 1413 | O21: =SUM(G21:L21) -> 799 | P21: =SUM(N21:N31) -> 12744 | Q21: =IF($A21<>"",$A21,Q20) -> March | R21: =IF($E21>0,$G21+2*$H21+$I21+2*$J21+$K21+2*$L21,0) -> 1413 | S21: =IF($E21>0,SUM($G21:$L21),0) -> 799
C22: SALGUEIRO | D22: MAE | E22: 46078.424 | F22: 46082.269 | G22: 231 | H22: 135 | I22: 159 | J22: 198 | K22: 0 | L22: 0 | M22: 26 | N22: =G22+H22*2+I22+J22*2+K22+L22*2 -> 1056 | O22: =SUM(G22:L22) -> 723 | Q22: =IF($A22<>"",$A22,Q21) -> March | R22: =IF($E22>0,$G22+2*$H22+$I22+2*$J22+$K22+2*$L22,0) -> 1056 | S22: =IF($E22>0,SUM($G22:$L22),0) -> 723
C23: MSC WAVE F | D23: MSC | E23: 46082.372 | F23: 46083.754 | G23: 127 | H23: 62 | I23: 13 | J23: 41 | K23: 67 | L23: 8 | M23: 0 | N23: =G23+H23*2+I23+J23*2+K23+L23*2 -> 429 | O23: =SUM(G23:L23) -> 318 | Q23: =IF($A23<>"",$A23,Q22) -> March | R23: =IF($E23>0,$G23+2*$H23+$I23+2*$J23+$K23+2*$L23,0) -> 429 | S23: =IF($E23>0,SUM($G23:$L23),0) -> 318
C24: AURETTE A | D24: CMA | E24: 46083.842 | F24: 46089.049 | G24: 203 | H24: 236 | I24: 62 | J24: 136 | K24: 202 | L24: 175 | M24: 26 | N24: =G24+H24*2+I24+J24*2+K24+L24*2 -> 1561 | O24: =SUM(G24:L24) -> 1014 | Q24: =IF($A24<>"",$A24,Q23) -> March | R24: =IF($E24>0,$G24+2*$H24+$I24+2*$J24+$K24+2*$L24,0) -> 1561 | S24: =IF($E24>0,SUM($G24:$L24),0) -> 1014
C25: HORIZON | D25: MAE | E25: 46091.471 | F25: 46095.358 | G25: 234 | H25: 254 | I25: 86 | J25: 53 | K25: 41 | L25: 340 | M25: 26 | N25: =G25+H25*2+I25+J25*2+K25+L25*2 -> 1655 | O25: =SUM(G25:L25) -> 1008 | Q25: =IF($A25<>"",$A25,Q24) -> March | R25: =IF($E25>0,$G25+2*$H25+$I25+2*$J25+$K25+2*$L25,0) -> 1655 | S25: =IF($E25>0,SUM($G25:$L25),0) -> 1008
C26: MATILDE A | D26: OBT | E26: 46096.386 | F26: 46098.344 | G26: 68 | H26: 216 | I26: 1 | J26: 100 | K26: 54 | L26: 90 | M26: 16 | N26: =G26+H26*2+I26+J26*2+K26+L26*2 -> 935 | O26: =SUM(G26:L26) -> 529 | Q26: =IF($A26<>"",$A26,Q25) -> March | R26: =IF($E26>0,$G26+2*$H26+$I26+2*$J26+$K26+2*$L26,0) -> 935 | S26: =IF($E26>0,SUM($G26:$L26),0) -> 529
C27: CONTSHIP GIN | D27: CMA | E27: 46099.021 | F27: 46103.812 | G27: 103 | H27: 273 | I27: 1 | J27: 23 | K27: 203 | L27: 219 | M27: 28 | N27: =G27+H27*2+I27+J27*2+K27+L27*2 -> 1337 | O27: =SUM(G27:L27) -> 822 | Q27: =IF($A27<>"",$A27,Q26) -> March | R27: =IF($E27>0,$G27+2*$H27+$I27+2*$J27+$K27+2*$L27,0) -> 1337 | S27: =IF($E27>0,SUM($G27:$L27),0) -> 822
C28: SALGUEIRO | D28: MAE | E28: 46102.438 | F28: 46105.844 | G28: 215 | H28: 218 | I28: 78 | J28: 107 | K28: 6 | L28: 186 | M28: 26 | N28: =G28+H28*2+I28+J28*2+K28+L28*2 -> 1321 | O28: =SUM(G28:L28) -> 810 | Q28: =IF($A28<>"",$A28,Q27) -> March | R28: =IF($E28>0,$G28+2*$H28+$I28+2*$J28+$K28+2*$L28,0) -> 1321 | S28: =IF($E28>0,SUM($G28:$L28),0) -> 810
C29: MSC TIANA F | D29: MSC | E29: 46105.979 | F29: 46109.396 | G29: 204 | H29: 231 | I29: 11 | J29: 99 | K29: 475 | L29: 52 | M29: 28 | N29: =G29+H29*2+I29+J29*2+K29+L29*2 -> 1454 | O29: =SUM(G29:L29) -> 1072 | Q29: =IF($A29<>"",$A29,Q28) -> March | R29: =IF($E29>0,$G29+2*$H29+$I29+2*$J29+$K29+2*$L29,0) -> 1454 | S29: =IF($E29>0,SUM($G29:$L29),0) -> 1072
C30: MAERSK REGENSBURG | D30: MAE | E30: 46107.5 | F30: 46110.096 | G30: 207 | H30: 204 | I30: 0 | J30: 41 | K30: 206 | L30: 141 | M30: 26 | N30: =G30+H30*2+I30+J30*2+K30+L30*2 -> 1185 | O30: =SUM(G30:L30) -> 799 | Q30: =IF($A30<>"",$A30,Q29) -> March | R30: =IF($E30>0,$G30+2*$H30+$I30+2*$J30+$K30+2*$L30,0) -> 1185 | S30: =IF($E30>0,SUM($G30:$L30),0) -> 799
C31: MSC WAVE F | D31: MSC | E31: 46110.226 | F31: 46111.354 | G31: 101 | H31: 89 | I31: 2 | J31: 2 | K31: 77 | L31: 18 | M31: 0 | N31: =G31+H31*2+I31+J31*2+K31+L31*2 -> 398 | O31: =SUM(G31:L31) -> 289 | Q31: =IF($A31<>"",$A31,Q30) -> March | R31: =IF($E31>0,$G31+2*$H31+$I31+2*$J31+$K31+2*$L31,0) -> 398 | S31: =IF($E31>0,SUM($G31:$L31),0) -> 289
A32: April | B32: =COUNTA(C32:C41) -> 10 | C32: MARTI SPIRIT | D32: MAE | E32: 46111.433 | F32: 46113.146 | G32: 184 | H32: 319 | I32: 0 | J32: 0 | K32: 50 | L32: 100 | M32: 28 | N32: =G32+H32*2+I32+J32*2+K32+L32*2 -> 1072 | O32: =SUM(G32:L32) -> 653 | P32: =SUM(N32:N41) -> 12671 | Q32: =IF($A32<>"",$A32,Q31) -> April | R32: =IF($E32>0,$G32+2*$H32+$I32+2*$J32+$K32+2*$L32,0) -> 1072 | S32: =IF($E32>0,SUM($G32:$L32),0) -> 653
C33: HORIZON | D33: MAE | E33: 46117.738 | F33: 46120.367 | G33: 75 | H33: 361 | I33: 10 | J33: 101 | K33: 217 | L33: 109 | M33: 24 | N33: =G33+H33*2+I33+J33*2+K33+L33*2 -> 1444 | O33: =SUM(G33:L33) -> 873 | Q33: =IF($A33<>"",$A33,Q32) -> April | R33: =IF($E33>0,$G33+2*$H33+$I33+2*$J33+$K33+2*$L33,0) -> 1444 | S33: =IF($E33>0,SUM($G33:$L33),0) -> 873
C34: AURETTE A | D34: CMA | E34: 46120.431 | F34: 46123.028 | G34: 170 | H34: 176 | I34: 10 | J34: 39 | K34: 122 | L34: 225 | M34: 20 | N34: =G34+H34*2+I34+J34*2+K34+L34*2 -> 1182 | O34: =SUM(G34:L34) -> 742 | Q34: =IF($A34<>"",$A34,Q33) -> April | R34: =IF($E34>0,$G34+2*$H34+$I34+2*$J34+$K34+2*$L34,0) -> 1182 | S34: =IF($E34>0,SUM($G34:$L34),0) -> 742
C35: MSC TIANA F | D35: MSC | E35: 46123.125 | F35: 46126.458 | G35: 232 | H35: 206 | I35: 2 | J35: 7 | K35: 216 | L35: 256 | M35: 28 | N35: =G35+H35*2+I35+J35*2+K35+L35*2 -> 1388 | O35: =SUM(G35:L35) -> 919 | Q35: =IF($A35<>"",$A35,Q34) -> April | R35: =IF($E35>0,$G35+2*$H35+$I35+2*$J35+$K35+2*$L35,0) -> 1388 | S35: =IF($E35>0,SUM($G35:$L35),0) -> 919
C36: SALGUEIRO | D36: MAE | E36: 46123.448 | F36: 46127.218 | G36: 112 | H36: 306 | I36: 106 | J36: 103 | K36: 184 | L36: 204 | M36: 26 | N36: =G36+H36*2+I36+J36*2+K36+L36*2 -> 1628 | O36: =SUM(G36:L36) -> 1015 | Q36: =IF($A36<>"",$A36,Q35) -> April | R36: =IF($E36>0,$G36+2*$H36+$I36+2*$J36+$K36+2*$L36,0) -> 1628 | S36: =IF($E36>0,SUM($G36:$L36),0) -> 1015
C37: MATILDE A | D37: OBT | E37: 46126.554 | F37: 46128.883 | G37: 123 | H37: 296 | I37: 4 | J37: 8 | K37: 93 | L37: 212 | M37: 26 | N37: =G37+H37*2+I37+J37*2+K37+L37*2 -> 1252 | O37: =SUM(G37:L37) -> 736 | Q37: =IF($A37<>"",$A37,Q36) -> April | R37: =IF($E37>0,$G37+2*$H37+$I37+2*$J37+$K37+2*$L37,0) -> 1252 | S37: =IF($E37>0,SUM($G37:$L37),0) -> 736
C38: BF ESPERANZA | D38: MAE | E38: 46127.854 | F38: 46130.104 | G38: 86 | H38: 258 | I38: 22 | J38: 77 | K38: 1 | L38: 0 | M38: 8 | N38: =G38+H38*2+I38+J38*2+K38+L38*2 -> 779 | O38: =SUM(G38:L38) -> 444 | Q38: =IF($A38<>"",$A38,Q37) -> April | R38: =IF($E38>0,$G38+2*$H38+$I38+2*$J38+$K38+2*$L38,0) -> 779 | S38: =IF($E38>0,SUM($G38:$L38),0) -> 444
C39: EF ELDRA | D39: MAE | E39: 46128.969 | F39: 46132.781 | G39: 91 | H39: 383 | I39: 0 | J39: 0 | K39: 152 | L39: 337 | M39: 28 | N39: =G39+H39*2+I39+J39*2+K39+L39*2 -> 1683 | O39: =SUM(G39:L39) -> 963 | Q39: =IF($A39<>"",$A39,Q38) -> April | R39: =IF($E39>0,$G39+2*$H39+$I39+2*$J39+$K39+2*$L39,0) -> 1683 | S39: =IF($E39>0,SUM($G39:$L39),0) -> 963
C40: CONTSHIP GIN | D40: CMA | E40: 46132.938 | F40: 46137.076 | G40: 147 | H40: 311 | I40: 1 | J40: 0 | K40: 114 | L40: 153 | M40: 28 | N40: =G40+H40*2+I40+J40*2+K40+L40*2 -> 1190 | O40: =SUM(G40:L40) -> 726 | Q40: =IF($A40<>"",$A40,Q39) -> April | R40: =IF($E40>0,$G40+2*$H40+$I40+2*$J40+$K40+2*$L40,0) -> 1190 | S40: =IF($E40>0,SUM($G40:$L40),0) -> 726
...

Sheet 2025
A1: MONTH | B1: NO | C1: VESSEL NAME | D1: AGENT | E1: BERTHING | F1: DEPARTURE | G1: DISCHARGE | I1: FCL LOADING | K1: EMPTY LOADING | M1: TOTAL TEU | N1: TOTAL CONTAINERS | O1: MONTHLY TEU
G2: 20 | H2: 40 | I2: 20 | J2: 40 | K2: 20 | L2: 40
A3: January | B3: =COUNTA(C3:C11) -> 9 | C3: CONTSHIP LEX | D3: OBT | E3: 45655 | F3: 45659 | G3: 213 | H3: 248 | J3: 5 | K3: 197 | L3: 164 | M3: =G3+H3*2+I3+J3*2+K3+L3*2 -> 1244 | N3: =SUM(G3:L3) -> 827 | O3: =SUM(M3:M11) -> 11995
C4: MAERSK ROUBAX | D4: MAE | E4: 45659.842 | F4: 45663.778 | G4: 221 | H4: 193 | I4: 17 | J4: 2 | K4: 55 | L4: 335 | M4: =G4+H4*2+I4+J4*2+K4+L4*2 -> 1353 | N4: =SUM(G4:L4) -> 823
C5: AS FREYA | D5: MAE | E5: 45663.807 | F5: 45667.76 | G5: 15 | H5: 408 | I5: 11 | J5: 37 | K5: 32 | L5: 125 | M5: =G5+H5*2+I5+J5*2+K5+L5*2 -> 1198 | N5: =SUM(G5:L5) -> 628
C6: MSC NINA F | D6: MSC | E6: 45666.688 | F6: 45670.528 | G6: 246 | H6: 159 | I6: 4 | J6: 2 | K6: 158 | L6: 82 | M6: =G6+H6*2+I6+J6*2+K6+L6*2 -> 894 | N6: =SUM(G6:L6) -> 651
C7: AS FABIANA | D7: MAE | E7: 45670.938 | F7: 45675.769 | G7: 145 | H7: 443 | I7: 51 | J7: 11 | K7: 68 | L7: 282 | M7: =G7+H7*2+I7+J7*2+K7+L7*2 -> 1736 | N7: =SUM(G7:L7) -> 1000
C8: MSC ADA F | D8: MSC | E8: 45675.933 | F8: 45681.797 | G8: 291 | H8: 96 | I8: 0 | J8: 15 | K8: 215 | L8: 126 | M8: =G8+H8*2+I8+J8*2+K8+L8*2 -> 980 | N8: =SUM(G8:L8) -> 743
C9: EM HYDRA | D9: CMA | E9: 45677.889 | F9: 45686.49 | G9: 224 | H9: 373 | I9: 87 | J9: 19 | K9: 384 | L9: 282 | M9: =G9+H9*2+I9+J9*2+K9+L9*2 -> 2043 | N9: =SUM(G9:L9) -> 1369
C10: VICTORIAL L | D10: MAE | E10: 45681.808 | F10: 45687.807 | G10: 64 | H10: 337 | I10: 111 | J10: 15 | K10: 3 | L10: 357 | M10: =G10+H10*2+I10+J10*2+K10+L10*2 -> 1596 | N10: =SUM(G10:L10) -> 887
C11: BF CARODA | D11: MAE | E11: 45687.34 | F11: 45690.997 | G11: 10 | H11: 251 | I11: 61 | J11: 49 | K11: 0 | L11: 140 | M11: =G11+H11*2+I11+J11*2+K11+L11*2 -> 951 | N11: =SUM(G11:L11) -> 511
A12: February | B12: =COUNTA(C12:C16) -> 5 | C12: CONTSHIP LEX | D12: OBT | E12: 45691.076 | F12: 45694.562 | G12: 234 | H12: 240 | I12: 52 | J12: 6 | K12: 175 | L12: 241 | M12: =G12+H12*2+I12+J12*2+K12+L12*2 -> 1435 | N12: =SUM(G12:L12) -> 948 | O12: =SUM(M12:M16) -> 6492
C13: AURETTE A | D13: CMA | E13: 45694.604 | F13: 45696.604 | G13: 161 | H13: 247 | I13: 0 | J13: 0 | K13: 0 | L13: 40 | M13: =G13+H13*2+I13+J13*2+K13+L13*2 -> 735 | N13: =SUM(G13:L13) -> 448
C14: CC NOUADHIBOU | D14: CMA | E14: 45696.656 | F14: 45701.368 | G14: 209 | H14: 250 | I14: 50 | J14: 5 | K14: 157 | L14: 313 | M14: =G14+H14*2+I14+J14*2+K14+L14*2 -> 1552 | N14: =SUM(G14:L14) -> 984
C15: MSC NINA F | D15: MSC | E15: 45704.879 | F15: 45707.917 | G15: 280 | H15: 104 | I15: 24 | J15: 20 | K15: 266 | L15: 86 | M15: =G15+H15*2+I15+J15*2+K15+L15*2 -> 990 | N15: =SUM(G15:L15) -> 780
C16: AS FREYA | D16: MAE | E16: 45710.379 | F16: 45714.771 | G16: 182 | H16: 322 | I16: 132 | J16: 164 | K16: 2 | L16: 246 | M16: =G16+H16*2+I16+J16*2+K16+L16*2 -> 1780 | N16: =SUM(G16:L16) -> 1048
A17: March | B17: =COUNTA(C17:C24) -> 8 | C17: MAERSK ROUBAX | D17: MAE | E17: 45720.444 | F17: 45723.99 | G17: 196 | H17: 263 | I17: 59 | J17: 100 | K17: 2 | L17: 278 | M17: =G17+H17*2+I17+J17*2+K17+L17*2 -> 1539 | N17: =SUM(G17:L17) -> 898 | O17: =SUM(M17:M24) -> 9243
C18: CONTSHIP LEX | D18: OBT | E18: 45724.073 | F18: 45727.475 | G18: 233 | H18: 233 | I18: 1 | J18: 38 | K18: 195 | L18: 302 | M18: =G18+H18*2+I18+J18*2+K18+L18*2 -> 1575 | N18: =SUM(G18:L18) -> 1002
C19: MSC NINA F | D19: MSC | E19: 45727.753 | F19: 45730.896 | G19: 187 | H19: 223 | I19: 12 | J19: 112 | K19: 343 | L19: 30 | M19: =G19+H19*2+I19+J19*2+K19+L19*2 -> 1272 | N19: =SUM(G19:L19) -> 907
C20: MSC ADA F | D20: MSC | E20: 45730.958 | F20: 45733.897 | G20: 282 | H20: 105 | I20: 0 | J20: 0 | K20: 69 | L20: 73 | M20: =G20+H20*2+I20+J20*2+K20+L20*2 -> 707 | N20: =SUM(G20:L20) -> 529
C21: AURETTE A | D21: CMA | E21: 45730.569 | F21: 45732.691 | G21: 235 | H21: 253 | I21: 0 | J21: 0 | K21: 0 | L21: 110 | M21: =G21+H21*2+I21+J21*2+K21+L21*2 -> 961 | N21: =SUM(G21:L21) -> 598
C22: BF CARODA | D22: MAE | E22: 45732.715 | F22: 45736.738 | G22: 75 | H22: 238 | I22: 73 | J22: 88 | K22: 6 | L22: 194 | M22: =G22+H22*2+I22+J22*2+K22+L22*2 -> 1194 | N22: =SUM(G22:L22) -> 674
C23: SALGUEIRO | D23: MAE | E23: 45740.929 | F23: 45742.903 | G23: 2 | H23: 54 | I23: 48 | J23: 89 | K23: 5 | L23: 13 | M23: =G23+H23*2+I23+J23*2+K23+L23*2 -> 367 | N23: =SUM(G23:L23) -> 211
C24: AURETTE A | D24: CMA | E24: 45743.875 | F24: 45748.767 | G24: 274 | H24: 168 | I24: 210 | J24: 69 | K24: 202 | L24: 234 | M24: =G24+H24*2+I24+J24*2+K24+L24*2 -> 1628 | N24: =SUM(G24:L24) -> 1157
A25: April | B25: =COUNTA(C25:C33) -> 9 | C25: CONTSHIP LEX | D25: OBT | E25: 45748.812 | F25: 45751.01 | G25: 196 | H25: 291 | I25: 1 | J25: 1 | K25: 216 | L25: 227 | M25: =G25+H25*2+I25+J25*2+K25+L25*2 -> 1451 | N25: =SUM(G25:L25) -> 932 | O25: =SUM(M25:M33) -> 11218
C26: MSC ADA F | D26: MSC | E26: 45751.5 | F26: 45754.768 | G26: 210 | H26: 225 | I26: 9 | J26: 22 | K26: 379 | L26: 181 | M26: =G26+H26*2+I26+J26*2+K26+L26*2 -> 1454 | N26: =SUM(G26:L26) -> 1026
C27: MAERSK ROUBAIX | D27: MAE | E27: 45754.951 | F27: 45758.075 | G27: 269 | H27: 142 | I27: 155 | J27: 98 | K27: 167 | L27: 202 | M27: =G27+H27*2+I27+J27*2+K27+L27*2 -> 1475 | N27: =SUM(G27:L27) -> 1033
C28: CALYPSO | D28: CMA | E28: 45757.771 | F28: 45760.802 | G28: 383 | H28: 225 | I28: 12 | J28: 11 | K28: 410 | L28: 294 | M28: =G28+H28*2+I28+J28*2+K28+L28*2 -> 1865 | N28: =SUM(G28:L28) -> 1335
C29: AURETTE A | D29: CMA | E29: 45762.75 | F29: 45764.65 | G29: 259 | H29: 252 | I29: 2 | J29: 5 | K29: 146 | L29: 158 | M29: =G29+H29*2+I29+J29*2+K29+L29*2 -> 1237 | N29: =SUM(G29:L29) -> 822
C30: MSC ADA F | D30: MSC | E30: 45766.955 | F30: 45769.84 | G30: 298 | H30: 86 | I30: 3 | J30: 16 | K30: 203 | L30: 170 | M30: =G30+H30*2+I30+J30*2+K30+L30*2 -> 1048 | N30: =SUM(G30:L30) -> 776
C31: SALGUEIRO | D31: MAE | E31: 45769.941 | F31: 45772.354 | G31: 141 | H31: 267 | I31: 19 | J31: 95 | K31: 2 | L31: 65 | M31: =G31+H31*2+I31+J31*2+K31+L31*2 -> 1016 | N31: =SUM(G31:L31) -> 589
C32: MSC SAGITTARIUS F | D32: MSC | E32: 45772.399 | F32: 45774.368 | G32: 150 | H32: 220 | I32: 0 | J32: 2 | K32: 114 | L32: 36 | M32: =G32+H32*2+I32+J32*2+K32+L32*2 -> 780 | N32: =SUM(G32:L32) -> 522
C33: CONTSHIP ONO | D33: MAE | E33: 45775.832 | F33: 45778.372 | G33: 249 | H33: 182 | I33: 58 | J33: 24 | K33: 157 | L33: 8 | M33: =G33+H33*2+I33+J33*2+K33+L33*2 -> 892 | N33: =SUM(G33:L33) -> 678
A34: May | B34: =COUNTA(C34:C42) -> 9 | C34: MARTI SPIRIT | D34: MAE | E34: 45779.417 | F34: 45781.556 | G34: 94 | H34: 384 | I34: 3 | J34: 102 | K34: 0 | L34: 0 | M34: =G34+H34*2+I34+J34*2+K34+L34*2 -> 1069 | N34: =SUM(G34:L34) -> 583 | O34: =SUM(M34:M42) -> 10414
C35: MSC ADA F | D35: MSC | E35: 45781.632 | F35: 45784.559 | G35: 278 | H35: 135 | I35: 6 | J35: 43 | K35: 208 | L35: 150 | M35: =G35+H35*2+I35+J35*2+K35+L35*2 -> 1148 | N35: =SUM(G35:L35) -> 820
C36: MAERSK ROUBAIX | D36: MAE | E36: 45783.406 | F36: 45786.483 | G36: 108 | H36: 355 | I36: 7 | J36: 81 | K36: 102 | L36: 84 | M36: =G36+H36*2+I36+J36*2+K36+L36*2 -> 1257 | N36: =SUM(G36:L36) -> 737
C37: MATADI EXPRESS | D37: OBT | E37: 45785.51 | F37: 45789.764 | G37: 151 | H37: 295 | I37: 50 | J37: 12 | K37: 139 | L37: 269 | M37: =G37+H37*2+I37+J37*2+K37+L37*2 -> 1492 | N37: =SUM(G37:L37) -> 916
C38: MSC SAGITTARIUS F | D38: MSC | E38: 45789.826 | F38: 45791.778 | G38: 246 | H38: 132 | I38: 3 | J38: 30 | K38: 157 | L38: 33 | M38: =G38+H38*2+I38+J38*2+K38+L38*2 -> 796 | N38: =SUM(G38:L38) -> 601
C39: SALGUEIRO | D39: MAE | E39: 45792.4 | F39: 45795.476 | G39: 117 | H39: 187 | I39: 65 | J39: 123 | K39: 83 | L39: 55 | M39: =G39+H39*2+I39+J39*2+K39+L39*2 -> 995 | N39: =SUM(G39:L39) -> 630
C40: AURETTE A | D40: CMA | E40: 45794.354 | F40: 45798.396 | G40: 200 | H40: 217 | I40: 106 | J40: 38 | K40: 43 | L40: 317 | M40: =G40+H40*2+I40+J40*2+K40+L40*2 -> 1493 | N40: =SUM(G40:L40) -> 921
...

Sheet 2024
A1: MONTH | B1: NO | C1: VESSEL NAME | D1: AGENT | E1: BERTHING | F1: DEPARTURE | G1: DISCHARGE | I1: FCL LOADING | K1: EMPTY LOADING | M1: TOTAL TEU | N1: TOTAL CONTAINERS | O1: MONTHLY TEU
G2: 20 | H2: 40 | I2: 20 | J2: 40 | K2: 20 | L2: 40
A3: January | B3: =COUNTA(C3:C11) -> 9 | C3: CC PLATON | D3: CMA | E3: 45293 | F3: 45299 | G3: 81 | H3: 183 | I3: 98 | J3: 46 | K3: 57 | L3: 275 | M3: =G3+H3*2+I3+J3*2+K3+L3*2 -> 1244 | N3: =SUM(G3:L3) -> 740 | O3: =SUM(M3:M11) -> 8288
C4: VICTORIA L | D4: MAE | E4: 45298 | F4: 45302 | G4: 166 | H4: 290 | I4: 12 | J4: 72 | K4: 86 | L4: 102 | M4: =G4+H4*2+I4+J4*2+K4+L4*2 -> 1192 | N4: =SUM(G4:L4) -> 728
C5: MSC ADA F | D5: MSC | E5: 45301 | F5: 45305 | G5: 121 | H5: 150 | J5: 12 | K5: 196 | L5: 75 | M5: =G5+H5*2+I5+J5*2+K5+L5*2 -> 791 | N5: =SUM(G5:L5) -> 554
C6: OKEE CUNO | D6: OBT | E6: 45303 | F6: 45305 | G6: 112 | H6: 67 | J6: 30 | K6: 15 | L6: 7 | M6: =G6+H6*2+I6+J6*2+K6+L6*2 -> 335 | N6: =SUM(G6:L6) -> 231
C7: CC NOUADHIBOU | D7: CMA | E7: 45308 | F7: 45314 | G7: 85 | H7: 244 | I7: 84 | J7: 11 | K7: 44 | L7: 225 | M7: =G7+H7*2+I7+J7*2+K7+L7*2 -> 1173 | N7: =SUM(G7:L7) -> 693
C8: OEL INDIA | D8: MAE | E8: 45308 | F8: 45312 | G8: 57 | H8: 205 | I8: 30 | J8: 122 | K8: 227 | L8: 121 | M8: =G8+H8*2+I8+J8*2+K8+L8*2 -> 1210 | N8: =SUM(G8:L8) -> 762
C9: AS FREYA | D9: MAE | E9: 45314 | F9: 45319 | G9: 142 | H9: 215 | I9: 89 | J9: 88 | K9: 113 | L9: 99 | M9: =G9+H9*2+I9+J9*2+K9+L9*2 -> 1148 | N9: =SUM(G9:L9) -> 746
C10: SAN VICENTE EXPRESS | D10: OBT | E10: 45315 | F10: 45316 | G10: 60 | H10: 48 | M10: =G10+H10*2+I10+J10*2+K10+L10*2 -> 156 | N10: =SUM(G10:L10) -> 108
C11: MAERSK ROUBAIX | D11: MAE | E11: 45319 | F11: 45323 | G11: 137 | H11: 168 | I11: 26 | J11: 114 | K11: 104 | L11: 104 | M11: =G11+H11*2+I11+J11*2+K11+L11*2 -> 1039 | N11: =SUM(G11:L11) -> 653
A12: February | B12: =COUNTA(C12:C20) -> 9 | C12: MSC LUNA F | D12: MSC | E12: 45327 | F12: 45329 | G12: 146 | H12: 143 | L12: 50 | M12: =G12+H12*2+I12+J12*2+K12+L12*2 -> 532 | N12: =SUM(G12:L12) -> 339 | O12: =SUM(M12:M20) -> 8833
C13: OEL INDIA | D13: MAE | E13: 45327 | F13: 45333 | G13: 164 | H13: 241 | I13: 44 | J13: 125 | K13: 49 | L13: 141 | M13: =G13+H13*2+I13+J13*2+K13+L13*2 -> 1271 | N13: =SUM(G13:L13) -> 764
C14: CC PLATON | D14: CMA | E14: 45332 | F14: 45338 | G14: 139 | H14: 248 | I14: 36 | J14: 17 | K14: 11 | L14: 95 | M14: =G14+H14*2+I14+J14*2+K14+L14*2 -> 906 | N14: =SUM(G14:L14) -> 546
C15: AS FREYA | D15: MAE | E15: 45332 | F15: 45338 | G15: 305 | H15: 185 | I15: 108 | J15: 47 | K15: 143 | L15: 194 | M15: =G15+H15*2+I15+J15*2+K15+L15*2 -> 1408 | N15: =SUM(G15:L15) -> 982
C16: OKEE CUNO | D16: OBT | E16: 45338 | F16: 45342 | G16: 124 | H16: 38 | I16: 2 | J16: 31 | K16: 171 | L16: 72 | M16: =G16+H16*2+I16+J16*2+K16+L16*2 -> 579 | N16: =SUM(G16:L16) -> 438
C17: CC NOUADHIBOU | D17: CMA | E17: 45340 | F17: 45344 | G17: 84 | H17: 195 | I17: 42 | J17: 1 | K17: 4 | L17: 185 | M17: =G17+H17*2+I17+J17*2+K17+L17*2 -> 892 | N17: =SUM(G17:L17) -> 511
C18: MSC ADA F | D18: MSC | E18: 45343 | F18: 45348 | G18: 229 | H18: 81 | J18: 71 | K18: 234 | L18: 32 | M18: =G18+H18*2+I18+J18*2+K18+L18*2 -> 831 | N18: =SUM(G18:L18) -> 647
C19: MAERSK ROUBAIX | D19: MAE | E19: 45344 | F19: 45348 | G19: 200 | H19: 232 | I19: 55 | J19: 105 | M19: =G19+H19*2+I19+J19*2+K19+L19*2 -> 929 | N19: =SUM(G19:L19) -> 592
C20: VICTORIA L | D20: MAE | E20: 45349 | F20: 45354 | G20: 248 | H20: 215 | I20: 36 | J20: 123 | K20: 201 | L20: 162 | M20: =G20+H20*2+I20+J20*2+K20+L20*2 -> 1485 | N20: =SUM(G20:L20) -> 985
A21: March | B21: =COUNTA(C21:C32) -> 12 | C21: MSC SUN F | D21: MSC | E21: 45353 | F21: 45357 | G21: 173 | H21: 89 | I21: 26 | J21: 24 | L21: 6 | M21: =G21+H21*2+I21+J21*2+K21+L21*2 -> 437 | N21: =SUM(G21:L21) -> 318 | O21: =SUM(M21:M32) -> 11055
C22: FRANZISKA | D22: MAE | E22: 45354 | F22: 45358 | G22: 287 | H22: 240 | I22: 35 | J22: 15 | K22: 79 | M22: =G22+H22*2+I22+J22*2+K22+L22*2 -> 911 | N22: =SUM(G22:L22) -> 656
C23: DIANE A | D23: CMA | E23: 45358 | F23: 45367 | G23: 250 | H23: 431 | I23: 100 | J23: 25 | K23: 82 | L23: 268 | M23: =G23+H23*2+I23+J23*2+K23+L23*2 -> 1880 | N23: =SUM(G23:L23) -> 1156
C24: AS FREYA | D24: MAE | E24: 45358 | F24: 45366 | G24: 161 | H24: 202 | I24: 8 | J24: 158 | K24: 230 | L24: 26 | M24: =G24+H24*2+I24+J24*2+K24+L24*2 -> 1171 | N24: =SUM(G24:L24) -> 785
C25: OKEE CUNO | D25: OBT | E25: 45371 | F25: 45375 | G25: 115 | H25: 106 | J25: 32 | K25: 142 | L25: 29 | M25: =G25+H25*2+I25+J25*2+K25+L25*2 -> 591 | N25: =SUM(G25:L25) -> 424
C26: OEL INDIA | D26: MAE | E26: 45367 | F26: 45373 | G26: 239 | H26: 159 | I26: 87 | J26: 55 | K26: 60 | L26: 160 | M26: =G26+H26*2+I26+J26*2+K26+L26*2 -> 1134 | N26: =SUM(G26:L26) -> 760
C27: MSC SAGITTARIUS | D27: MSC | E27: 45368 | F27: 45371 | G27: 181 | H27: 56 | I27: 2 | J27: 6 | L27: 50 | M27: =G27+H27*2+I27+J27*2+K27+L27*2 -> 407 | N27: =SUM(G27:L27) -> 295
C28: CC PLATON | D28: CMA | E28: 45373 | F28: 45376 | G28: 77 | H28: 40 | I28: 14 | J28: 31 | K28: 82 | L28: 181 | M28: =G28+H28*2+I28+J28*2+K28+L28*2 -> 677 | N28: =SUM(G28:L28) -> 425
C29: MAERSK ROUBAIX | D29: MAE | E29: 45376 | F29: 45378 | G29: 149 | H29: 250 | M29: =G29+H29*2+I29+J29*2+K29+L29*2 -> 649 | N29: =SUM(G29:L29) -> 399
C30: GEESKE | D30: MAE | E30: 45378 | F30: 45380 | G30: 244 | H30: 190 | L30: 100 | M30: =G30+H30*2+I30+J30*2+K30+L30*2 -> 824 | N30: =SUM(G30:L30) -> 534
C31: VICTORIA L | D31: MAE | E31: 45380 | F31: 45388 | G31: 299 | H31: 160 | I31: 164 | J31: 114 | K31: 297 | L31: 217 | M31: =G31+H31*2+I31+J31*2+K31+L31*2 -> 1742 | N31: =SUM(G31:L31) -> 1251
C32: MSC LUNA F | D32: MSC | E32: 45381 | F32: 45385 | G32: 118 | H32: 56 | J32: 5 | K32: 4 | L32: 194 | M32: =G32+H32*2+I32+J32*2+K32+L32*2 -> 632 | N32: =SUM(G32:L32) -> 377
A33: April | B33: =COUNTA(C33:C42) -> 10 | C33: AS FREYA | D33: MAE | E33: 45385 | F33: 45391 | G33: 335 | H33: 132 | K33: 235 | L33: 301 | M33: =G33+H33*2+I33+J33*2+K33+L33*2 -> 1436 | N33: =SUM(G33:L33) -> 1003 | O33: =SUM(M33:M42) -> 11436
C34: AS FABIANA | D34: MAE | E34: 45388 | F34: 45395 | G34: 223 | H34: 132 | I34: 108 | J34: 99 | K34: 179 | L34: 70 | M34: =G34+H34*2+I34+J34*2+K34+L34*2 -> 1112 | N34: =SUM(G34:L34) -> 811
C35: CC NOUADHIBOU | D35: CMA | E35: 45391 | F35: 45396 | G35: 46 | H35: 138 | I35: 29 | J35: 21 | K35: 69 | L35: 156 | M35: =G35+H35*2+I35+J35*2+K35+L35*2 -> 774 | N35: =SUM(G35:L35) -> 459
C36: OEL INDIA | D36: MAE | E36: 45395 | F36: 45400 | G36: 129 | H36: 268 | J36: 5 | K36: 421 | L36: 196 | M36: =G36+H36*2+I36+J36*2+K36+L36*2 -> 1488 | N36: =SUM(G36:L36) -> 1019
C37: MSC SUN F | D37: MSC | E37: 45396 | F37: 45403 | G37: 221 | H37: 185 | I37: 3 | K37: 506 | L37: 127 | M37: =G37+H37*2+I37+J37*2+K37+L37*2 -> 1354 | N37: =SUM(G37:L37) -> 1042
C38: JONATHAN P | D38: OBT | E38: 45400 | F38: 45403 | G38: 20 | H38: 74 | J38: 1 | K38: 111 | L38: 98 | M38: =G38+H38*2+I38+J38*2+K38+L38*2 -> 477 | N38: =SUM(G38:L38) -> 304
C39: EM HYDRA | D39: CMA | E39: 45403 | F39: 45410 | G39: 100 | H39: 236 | I39: 55 | J39: 3 | K39: 142 | L39: 298 | M39: =G39+H39*2+I39+J39*2+K39+L39*2 -> 1371 | N39: =SUM(G39:L39) -> 834
C40: VICTORIA L | D40: MAE | E40: 45406 | F40: 45410 | G40: 262 | H40: 195 | I40: 80 | J40: 72 | K40: 294 | L40: 132 | M40: =G40+H40*2+I40+J40*2+K40+L40*2 -> 1434 | N40: =SUM(G40:L40) -> 1035
...
